Workbook
Name Slicer_ticket_priority: #N/A
Name Slicer_ticket_status: #N/A
Name Slicer_ticket_type: #N/A

Sheet _Static_Dashboard
B1: Support Tickets Dashboard

Sheet Dashboard
B1: Customer Support Performance & Satisfaction Dashboard
C13: Total Tickets | F13: AVG CSAT Rating | I13: AVG Resolution Time | L13: Closed Rate (%) | O13: Backlog Tickets | R13: Low CSAT Rate
C15: =IFERROR(GETPIVOTDATA("Count of ticket_id",'Pivot tables'!$A$3),"N/A") -> 8469 | F15: =IFERROR(GETPIVOTDATA("Average of customer_satisfaction_rating",'Pivot tables'!$A$3),"N/A") -> 2.9913326 | I15: =IFERROR(GETPIVOTDATA("Average of Resolution_Time_Clean",'Pivot tables'!$A$3),"N/A") -> 7.1096866 | L15: =IFERROR('Pivot tables'!C11,"N/A") -> 0.32695714 | O15: =IFERROR('Pivot tables'!D11,"N/A") -> 5700 | R15: =IFERROR('Pivot tables'!D193,"N/A") -> 0.39797761

Sheet Tickets Data
A1: ticket_id | B1: customer_name | C1: customer_email | D1: customer_age | E1: customer_gender | F1: product_purchased | G1: date_of_purchase | H1: ticket_type | I1: ticket_subject | J1: ticket_description | K1: ticket_status | L1: resolution | M1: ticket_priority | N1: ticket_channel | O1: first_response_at | P1: resolved_at | Q1: customer_satisfaction_rating | R1: resolution_time_hours | S1: is_closed | T1: is_backlog | U1: is_low_csat | V1: Resolution_Time_Clean
A2: 1 | B2: Marisa Obrien | C2: carrollallison@example.com | D2: 32 | E2: Other | F2: GoPro Hero | G2: 44277 | H2: Technical issue | I2: Product setup | J2: I'm having an issue with the {product_purchased}. Please assist. Your billing zip code is: 71701. We appreciate that you have requested a website address. Please double check your email address. I've tried troubleshooting steps mentioned in the user manual, but the issue persists. | K2: Pending Customer Response | M2: Critical | N2: Social media | O2: 45078.511 | S2: 0 | T2: 1 | U2: 0 | V2: =IF(OR(tickets_cleaned[[#This Row],[resolution_time_hours]]="", tickets_cleaned[[#This Row],[resolution_time_hours]]<0),"",tickets_cleaned[[#This Row],[resolution_time_hours]])
A3: 2 | B3: Jessica Rios | C3: clarkeashley@example.com | D3: 42 | E3: Female | F3: LG Smart TV | G3: 44338 | H3: Technical issue | I3: Peripheral compatibility | J3: I'm having an issue with the {product_purchased}. Please assist. If you need to change an existing product. I'm having an issue with the {product_purchased}. Please assist. If The issue I'm facing is intermittent. Sometimes it works fine, but other times it acts up unexpectedly. | K3: Pending Customer Response | M3: Critical | N3: Chat | O3: 45078.698 | S3: 0 | T3: 1 | U3: 0 | V3: =IF(OR(tickets_cleaned[[#This Row],[resolution_time_hours]]="", tickets_cleaned[[#This Row],[resolution_time_hours]]<0),"",tickets_cleaned[[#This Row],[resolution_time_hours]])
A4: 3 | B4: Christopher Robbins | C4: gonzalestracy@example.com | D4: 48 | E4: Other | F4: Dell XPS | G4: 44026 | H4: Technical issue | I4: Network problem | J4: I'm facing a problem with my {product_purchased}. The {product_purchased} is not turning on. It was working fine until yesterday, but now it doesn't respond. 1.8.3 I really I'm using the original charger that came with my {product_purchased}, but it's not charging properly. | K4: Closed | L4: Case maybe show recently my computer follow. | M4: Low | N4: Social media | O4: 45078.468 | P4: 45078.754 | Q4: 3 | R4: 6 | S4: 1 | T4: 0 | U4: 0 | V4: =IF(OR(tickets_cleaned[[#This Row],[resolution_time_hours]]="", tickets_cleaned[[#This Row],[resolution_time_hours]]<0),"",tickets_cleaned[[#This Row],[resolution_time_hours]]) -> 6
A5: 4 | B5: Christina Dillon | C5: bradleyolson@example.org | D5: 27 | E5: Female | F5: Microsoft Office | G5: 44148 | H5: Billing inquiry | I5: Account access | J5: I'm having an issue with the {product_purchased}. Please assist. If you have a problem you're interested in and I'd love to see this happen, please check out the Feedback. I've already contacted customer support multiple times, but the issue remains unresolved. | K5: Closed | L5: Try capital clearly never color toward story. | M5: Low | N5: Social media | O5: 45078.312 | P5: 45078.082 | Q5: 3 | S5: 1 | T5: 0 | U5: 0 | V5: =IF(OR(tickets_cleaned[[#This Row],[resolution_time_hours]]="", tickets_cleaned[[#This Row],[resolution_time_hours]]<0),"",tickets_cleaned[[#This Row],[resolution_time_hours]])
A6: 5 | B6: Alexander Carroll | C6: bradleymark@example.com | D6: 67 | E6: Female | F6: Autodesk AutoCAD | G6: 43865 | H6: Billing inquiry | I6: Data loss | J6: I'm having an issue with the {product_purchased}. Please assist. Note: The seller is not responsible for any damages arising out of the delivery of the battleground game. Please have the game in good condition and shipped to you I've noticed a sudden decrease in battery life on my {product_purchased}. It used to last much longer. | K6: Closed | L6: West decision evidence bit. | M6: Low | N6: Email | O6: 45078.009 | P6: 45078.829 | Q6: 1 | R6: 19 | S6: 1 | T6: 0 | U6: 1 | V6: =IF(OR(tickets_cleaned[[#This Row],[resolution_time_hours]]="", tickets_cleaned[[#This Row],[resolution_time_hours]]<0),"",tickets_cleaned[[#This Row],[resolution_time_hours]]) -> 19
A7: 6 | B7: Rebecca Fleming | C7: sheenasmith@example.com | D7: 53 | E7: Male | F7: Microsoft Office | G7: 44040 | H7: Cancellation request | I7: Payment issue | J7: I'm facing a problem with my {product_purchased}. The {product_purchased} is not turning on. It was working fine until yesterday, but now it doesn't respond. To remove the new {product_purch I've checked for any available software updates for my {product_purchased}, but there are none. | K7: Open | M7: Low | N7: Social media | S7: 0 | T7: 1 | U7: 0 | V7: =IF(OR(tickets_cleaned[[#This Row],[resolution_time_hours]]="", tickets_cleaned[[#This Row],[resolution_time_hours]]<0),"",tickets_cleaned[[#This Row],[resolution_time_hours]])
A8: 7 | B8: Jacqueline Wright | C8: donaldkeith@example.org | D8: 24 | E8: Other | F8: Microsoft Surface | G8: 43884 | H8: Product inquiry | I8: Refund request | J8: I'm unable to access my {product_purchased} account. It keeps displaying an 'Invalid Credentials' error, even though I'm using the correct login information. How can I regain access to my account? Solution 1 I'm unable to find the option to perform the desired action in the {product_purchased}. Could you please guide me through the steps? | K8: Open | M8: Critical | N8: Social media | S8: 0 | T8: 1 | U8: 0 | V8: =IF(OR(tickets_cleaned[[#This Row],[resolution_time_hours]]="", tickets_cleaned[[#This Row],[resolution_time_hours]]<0),"",tickets_cleaned[[#This Row],[resolution_time_hours]])
A9: 8 | B9: Denise Lee | C9: joelwilliams@example.com | D9: 23 | E9: Male | F9: Philips Hue Lights | G9: 44052 | H9: Refund request | I9: Battery life | J9: I'm having an issue with the {product_purchased}. Please assist. (Thanks) I will contact all my suppliers and confirm. Please try and find out whether their inventory is currently stocked, or any other reason. I am I've performed a factory reset on my {product_purchased}, hoping it would resolve the problem, but it didn't help. | K9: Open | M9: Critical | N9: Social media | S9: 0 | T9: 1 | U9: 0 | V9: =IF(OR(tickets_cleaned[[#This Row],[resolution_time_hours]]="", tickets_cleaned[[#This Row],[resolution_time_hours]]<0),"",tickets_cleaned[[#This Row],[resolution_time_hours]])
A10: 9 | B10: Nicolas Wilson | C10: joshua24@example.com | D10: 60 | E10: Other | F10: Fitbit Versa Smartwatch | G10: 44028 | H10: Technical issue | I10: Installation support | J10: I'm having an issue with the {product_purchased}. Please assist. Thank you. {product_purchased} is not the exact type you might prefer, they use the exact same method for different uses. Please help I've recently updated the firmware of my {product_purchased}, and the issue started happening afterward. Could it be related to the update? | K10: Pending Customer Response | M10: Low | N10: Social media | O10: 45078.439 | S10: 0 | T10: 1 | U10: 0 | V10: =IF(OR(tickets_cleaned[[#This Row],[resolution_time_hours]]="", tickets_cleaned[[#This Row],[resolution_time_hours]]<0),"",tickets_cleaned[[#This Row],[resolution_time_hours]])
A11: 10 | B11: William Dawson | C11: clopez@example.com | D11: 27 | E11: Male | F11: Dyson Vacuum Cleaner | G11: 43896 | H11: Refund request | I11: Payment issue | J11: My {product_purchased} is making strange noises and not functioning properly. I suspect there might be a hardware issue. Can you please help me with this? } If we can, please send a "request" to dav The issue I'm facing is intermittent. Sometimes it works fine, but other times it acts up unexpectedly. | K11: Pending Customer Response | M11: Critical | N11: Phone | O11: 45078.393 | S11: 0 | T11: 1 | U11: 0 | V11: =IF(OR(tickets_cleaned[[#This Row],[resolution_time_hours]]="", tickets_cleaned[[#This Row],[resolution_time_hours]]<0),"",tickets_cleaned[[#This Row],[resolution_time_hours]])
A12: 11 | B12: Joseph Moreno | C12: mbrown@example.org | D12: 48 | E12: Male | F12: Nintendo Switch | G12: 44215 | H12: Cancellation request | I12: Data loss | J12: I'm having an issue with the {product_purchased}. Please assist. 1-800-799-0808. Product Search: What's New in 2-3-4-5? Report Feedback Customer Service is your best I'm using the original charger that came with my {product_purchased}, but it's not charging properly. | K12: Closed | L12: Measure tonight surface feel forward. | M12: High | N12: Phone | O12: 45078.741 | P12: 45077.994 | Q12: 1 | S12: 1 | T12: 0 | U12: 1 | V12: =IF(OR(tickets_cleaned[[#This Row],[resolution_time_hours]]="", tickets_cleaned[[#This Row],[resolution_time_hours]]<0),"",tickets_cleaned[[#This Row],[resolution_time_hours]])
A13: 12 | B13: Brandon Arnold | C13: davisjohn@example.net | D13: 51 | E13: Male | F13: Microsoft Xbox Controller | G13: 44493 | H13: Product inquiry | I13: Software bug | J13: I'm having an issue with the {product_purchased}. Please assist. 4. It is possible that we cannot find some type of text or a product name to identify someone like Mr. Brown. 5. On the I've reviewed the troubleshooting steps on the official support website, but they didn't resolve the problem. | K13: Closed | L13: Measure there house management pick knowledge trade. | M13: High | N13: Chat | O13: 45078.504 | P13: 45078.394 | Q13: 1 | S13: 1 | T13: 0 | U13: 1 | V13: =IF(OR(tickets_cleaned[[#This Row],[resolution_time_hours]]="", tickets_cleaned[[#This Row],[resolution_time_hours]]<0),"",tickets_cleaned[[#This Row],[resolution_time_hours]])
A14: 13 | B14: Tamara Hahn | C14: jensenwilliam@example.net | D14: 27 | E14: Other | F14: Nintendo Switch Pro Controller | G14: 44342 | H14: Technical issue | I14: Hardware issue | J14: I'm having an issue with the {product_purchased}. Please assist. CQW: Why didn't I send him the invoice? Thanks a lot. L: He's like the best customer I've met. I've noticed that the issue occurs consistently when I use a specific feature or application on my {product_purchased}. | K14: Pending Customer Response | M14: Low | N14: Chat | O14: 45078.794 | S14: 0 | T14: 1 | U14: 0 | V14: =IF(OR(tickets_cleaned[[#This Row],[resolution_time_hours]]="", tickets_cleaned[[#This Row],[resolution_time_hours]]<0),"",tickets_cleaned[[#This Row],[resolution_time_hours]])
A15: 14 | B15: Sandra Barnes | C15: gwendolyn51@example.net | D15: 65 | E15: Other | F15: Nest Thermostat | G15: 44025 | H15: Technical issue | I15: Product setup | J15: I've recently set up my {product_purchased}, but it fails to connect to any available networks. What steps should I take to troubleshoot this issue? I can't find the 'Product_IP' field of the I'm concerned about the security of my {product_purchased} and would like to ensure that my data is safe. | K15: Pending Customer Response | M15: Low | N15: Chat | O15: 45078.858 | S15: 0 | T15: 1 | U15: 0 | V15: =IF(OR(tickets_cleaned[[#This Row],[resolution_time_hours]]="", tickets_cleaned[[#This Row],[resolution_time_hours]]<0),"",tickets_cleaned[[#This Row],[resolution_time_hours]])
A16: 15 | B16: Amy Hill | C16: medinasteven@example.net | D16: 48 | E16: Female | F16: Sony PlayStation | G16: 43890 | H16: Billing inquiry | I16: Product setup | J16: I'm having an issue with the {product_purchased}. Please assist. Product Name: TPUBASK3E3KQ0 Join Date: Oct 2007 Posts: 11,532 Quote: I've recently updated the firmware of my {product_purchased}, and the issue started happening afterward. Could it be related to the update? | K16: Closed | L16: Officer moment world sing parent available. | M16: High | N16: Chat | O16: 45078.266 | P16: 45077.965 | Q16: 4 | S16: 1 | T16: 0 | U16: 0 | V16: =IF(OR(tickets_cleaned[[#This Row],[resolution_time_hours]]="", tickets_cleaned[[#This Row],[resolution_time_hours]]<0),"",tickets_cleaned[[#This Row],[resolution_time_hours]])
A17: 16 | B17: Elizabeth Foley | C17: amy41@example.net | D17: 18 | E17: Other | F17: GoPro Action Camera | G17: 44371 | H17: Billing inquiry | I17: Product recommendation | J17: I'm having an issue with the {product_purchased}. Please assist. Please note, you might have already paid for this product, which means spectators are not buying any of the products from the sale as their donations will go straight I've noticed a sudden decrease in battery life on my {product_purchased}. It used to last much longer. | K17: Pending Customer Response | M17: High | N17: Social media | O17: 45078.632 | S17: 0 | T17: 1 | U17: 0 | V17: =IF(OR(tickets_cleaned[[#This Row],[resolution_time_hours]]="", tickets_cleaned[[#This Row],[resolution_time_hours]]<0),"",tickets_cleaned[[#This Row],[resolution_time_hours]])
A18: 17 | B18: Julia Salazar | C18: watkinsbarbara@example.com | D18: 63 | E18: Other | F18: Xbox | G18: 44482 | H18: Product inquiry | I18: Account access | J18: I'm having an issue with the {product_purchased}. Please assist. - Acknowledgement: Thanks to Dan for the tip. When you purchase a new product from my store or from your local retailer, they will also provide I'm concerned about the security of my {product_purchased} and would like to ensure that my data is safe. | K18: Closed | L18: Seek evidence book collection catch. | M18: Critical | N18: Chat | O18: 45078.824 | P18: 45078.666 | Q18: 4 | S18: 1 | T18: 0 | U18: 0 | V18: =IF(OR(tickets_cleaned[[#This Row],[resolution_time_hours]]="", tickets_cleaned[[#This Row],[resolution_time_hours]]<0),"",tickets_cleaned[[#This Row],[resolution_time_hours]])
A19: 18 | B19: Joshua Castillo | C19: mooredeborah@example.org | D19: 56 | E19: Female | F19: Microsoft Xbox Controller | G19: 44081 | H19: Product inquiry | I19: Payment issue | J19: I'm having an issue with the {product_purchased}. Please assist. Thanks!" * [0] - [0] - [0] - [0] If this product is sold and you have not used any I've reviewed the troubleshooting steps on the official support website, but they didn't resolve the problem. | K19: Pending Customer Response | M19: High | N19: Chat | O19: 45078.878 | S19: 0 | T19: 1 | U19: 0 | V19: =IF(OR(tickets_cleaned[[#This Row],[resolution_time_hours]]="", tickets_cleaned[[#This Row],[resolution_time_hours]]<0),"",tickets_cleaned[[#This Row],[resolution_time_hours]])
A20: 19 | B20: Wendy Davis | C20: brenda20@example.net | D20: 19 | E20: Male | F20: LG Washing Machine | G20: 44462 | H20: Product inquiry | I20: Peripheral compatibility | J20: I'm having an issue with the {product_purchased}. Please assist. I want to be an active member of our community on YouTube... The issue I'm facing is intermittent. Sometimes it works fine, but other times it acts up unexpectedly. | K20: Open | M20: High | N20: Social media | S20: 0 | T20: 1 | U20: 0 | V20: =IF(OR(tickets_cleaned[[#This Row],[resolution_time_hours]]="", tickets_cleaned[[#This Row],[resolution_time_hours]]<0),"",tickets_cleaned[[#This Row],[resolution_time_hours]])
A21: 20 | B21: Jeffrey Robertson | C21: jameslopez@example.com | D21: 39 | E21: Female | F21: Canon EOS | G21: 44263 | H21: Refund request | I21: Software bug | J21: I'm having an issue with the {product_purchased}. Please assist. I'm having an issue with the product_purchased}. Please assist. Customer Reviewer: My Husband was able to take an order from Apple I've checked for any available software updates for my {product_purchased}, but there are none. | K21: Closed | L21: Wish mouth build resource though. | M21: Low | N21: Chat | O21: 45078.032 | P21: 45078.854 | Q21: 5 | R21: 19 | S21: 1 | T21: 0 | U21: 0 | V21: =IF(OR(tickets_cleaned[[#This Row],[resolution_time_hours]]="", tickets_cleaned[[#This Row],[resolution_time_hours]]<0),"",tickets_cleaned[[#This Row],[resolution_time_hours]]) -> 19
A22: 21 | B22: Suzanne Holmes | C22: rogermcgrath@example.net | D22: 28 | E22: Other | F22: HP Pavilion | G22: 44347 | H22: Refund request | I22: Payment issue | J22: I'm having an issue with the {product_purchased}. Please assist. " -name "Microsoft Surface Pro. " " -version 1.10.2 "1.10.2" " -usage I've checked for any available software updates for my {product_purchased}, but there are none. | K22: Pending Customer Response | M22: High | N22: Chat | O22: 45078.214 | S22: 0 | T22: 1 | U22: 0 | V22: =IF(OR(tickets_cleaned[[#This Row],[resolution_time_hours]]="", tickets_cleaned[[#This Row],[resolution_time_hours]]<0),"",tickets_cleaned[[#This Row],[resolution_time_hours]])
A23: 22 | B23: Tanner Conley | C23: zbond@example.net | D23: 66 | E23: Male | F23: Fitbit Versa Smartwatch | G23: 43865 | H23: Cancellation request | I23: Installation support | J23: I'm having an issue with the {product_purchased}. Please assist. The email address should change to: customer@julietr.com, as there is a unique id number unique for each product. You I've tried different settings and configurations on my {product_purchased}, but the issue persists. | K23: Pending Customer Response | M23: Critical | N23: Social media | O23: 45077.998 | S23: 0 | T23: 1 | U23: 0 | V23: =IF(OR(tickets_cleaned[[#This Row],[resolution_time_hours]]="", tickets_cleaned[[#This Row],[resolution_time_hours]]<0),"",tickets_cleaned[[#This Row],[resolution_time_hours]])
A24: 23 | B24: Stephanie Nelson DVM | C24: ljohnson@example.org | D24: 54 | E24: Female | F24: Xbox | G24: 43872 | H24: Cancellation request | I24: Delivery problem | J24: I'm having an issue with the {product_purchased}. Please assist. (And if need be this time, that could help.) 1.3.2.1 Update my version to 3.0 or more. The issue I'm facing is intermittent. Sometimes it works fine, but other times it acts up unexpectedly. | K24: Open | M24: Medium | N24: Social media | S24: 0 | T24: 1 | U24: 0 | V24: =IF(OR(tickets_cleaned[[#This Row],[resolution_time_hours]]="", tickets_cleaned[[#This Row],[resolution_time_hours]]<0),"",tickets_cleaned[[#This Row],[resolution_time_hours]])
A25: 24 | B25: Antonio Scott | C25: carlsonmatthew@example.org | D25: 63 | E25: Female | F25: Nintendo Switch Pro Controller | G25: 44414 | H25: Technical issue | I25: Refund request | J25: I'm having an issue with the {product_purchased}. Please assist. I'll take care of those. I've performed a factory reset on my {product_purchased}, hoping it would resolve the problem, but it didn't help. | K25: Pending Customer Response | M25: Low | N25: Social media | O25: 45078.379 | S25: 0 | T25: 1 | U25: 0 | V25: =IF(OR(tickets_cleaned[[#This Row],[resolution_time_hours]]="", tickets_cleaned[[#This Row],[resolution_time_hours]]<0),"",tickets_cleaned[[#This Row],[resolution_time_hours]])
A26: 25 | B26: John Cuevas | C26: lbarron@example.org | D26: 19 | E26: Male | F26: Amazon Kindle | G26: 44341 | H26: Product inquiry | I26: Display issue | J26: I'm having an issue with the {product_purchased}. Please assist. {product_purchased} does not represent the price which you received by the day immediately before the shipment date. In many cases, this is the I've noticed a sudden decrease in battery life on my {product_purchased}. It used to last much longer. | K26: Open | M26: Critical | N26: Email | S26: 0 | T26: 1 | U26: 0 | V26: =IF(OR(tickets_cleaned[[#This Row],[resolution_time_hours]]="", tickets_cleaned[[#This Row],[resolution_time_hours]]<0),"",tickets_cleaned[[#This Row],[resolution_time_hours]])
A27: 26 | B27: Gregory Bautista | C27: johnstonbeth@example.com | D27: 35 | E27: Other | F27: HP Pavilion | G27: 44382 | H27: Product inquiry | I27: Refund request | J27: My {product_purchased} is making strange noises and not functioning properly. I suspect there might be a hardware issue. Can you please help me with this? Thank you, Thank you for posting. It took me a I'm experiencing this issue on multiple devices of the same model, so it seems to be a widespread problem. | K27: Pending Customer Response | M27: Medium | N27: Social media | O27: 45078.793 | S27: 0 | T27: 1 | U27: 0 | V27: =IF(OR(tickets_cleaned[[#This Row],[resolution_time_hours]]="", tickets_cleaned[[#This Row],[resolution_time_hours]]<0),"",tickets_cleaned[[#This Row],[resolution_time_hours]])
A28: 27 | B28: Ryan Sharp | C28: pmercado@example.org | D28: 22 | E28: Other | F28: Lenovo ThinkPad | G28: 43953 | H28: Billing inquiry | I28: Cancellation request | J28: I'm encountering a software bug in the {product_purchased}. Whenever I try to perform a specific action, the application crashes. Are there any updates or fixes available? On Windows Vista, this is not possible. If you are I've performed a factory reset on my {product_purchased}, hoping it would resolve the problem, but it didn't help. | K28: Pending Customer Response | M28: Low | N28: Social media | O28: 45078.835 | S28: 0 | T28: 1 | U28: 0 | V28: =IF(OR(tickets_cleaned[[#This Row],[resolution_time_hours]]="", tickets_cleaned[[#This Row],[resolution_time_hours]]<0),"",tickets_cleaned[[#This Row],[resolution_time_hours]])
A29: 28 | B29: Michael Mcdowell | C29: jeffersonmichael@example.net | D29: 21 | E29: Other | F29: Fitbit Charge | G29: 44116 | H29: Cancellation request | I29: Product setup | J29: I'm having an issue with the {product_purchased}. Please assist. {{product_purchased}} must be a valid email address for your order and are valid for one week in advance. Please make your purchases as quickly as possible The issue I'm facing is intermittent. Sometimes it works fine, but other times it acts up unexpectedly. | K29: Open | M29: High | N29: Phone | S29: 0 | T29: 1 | U29: 0 | V29: =IF(OR(tickets_cleaned[[#This Row],[resolution_time_hours]]="", tickets_cleaned[[#This Row],[resolution_time_hours]]<0),"",tickets_cleaned[[#This Row],[resolution_time_hours]])
A30: 29 | B30: Christine Wang | C30: garciastacy@example.com | D30: 30 | E30: Other | F30: Fitbit Charge | G30: 43992 | H30: Technical issue | I30: Product recommendation | J30: I'm having an issue with the {product_purchased}. Please assist. Thank you." A statement from the consumer group had been released by Microsoft late on Tuesday afternoon. "The purchase of this product was made using a contract with I'm using the original charger that came with my {product_purchased}, but it's not charging properly. | K30: Closed | L30: Soldier we such inside. | M30: Critical | N30: Phone | O30: 45077.97 | P30: 45078.252 | Q30: 5 | R30: 6 | S30: 1 | T30: 0 | U30: 0 | V30: =IF(OR(tickets_cleaned[[#This Row],[resolution_time_hours]]="", tickets_cleaned[[#This Row],[resolution_time_hours]]<0),"",tickets_cleaned[[#This Row],[resolution_time_hours]]) -> 6
A31: 30 | B31: Austin George | C31: shericase@example.net | D31: 67 | E31: Male | F31: Xbox | G31: 44191 | H31: Cancellation request | I31: Cancellation request | J31: I'm having an issue with the {product_purchased}. Please assist. It's not possible to remove the missing content. I've already contacted customer support multiple times, but the issue remains unresolved. | K31: Closed | L31: Firm sort voice above which site arrive. | M31: Medium | N31: Phone | O31: 45078.038 | P31: 45078.766 | Q31: 1 | R31: 17 | S31: 1 | T31: 0 | U31: 1 | V31: =IF(OR(tickets_cleaned[[#This Row],[resolution_time_hours]]="", tickets_cleaned[[#This Row],[resolution_time_hours]]<0),"",tickets_cleaned[[#This Row],[resolution_time_hours]]) -> 17
A32: 31 | B32: Wendy Roberts | C32: jessicahenderson@example.net | D32: 22 | E32: Other | F32: Adobe Photoshop | G32: 44224 | H32: Billing inquiry | I32: Product setup | J32: I'm having an issue with the {product_purchased}. Please assist. I'm using a brand new product. What a strange situation. I've just purchased a brand new one. What to do? I've noticed that the issue occurs consistently when I use a specific feature or application on my {product_purchased}. | K32: Open | M32: Low | N32: Email | S32: 0 | T32: 1 | U32: 0 | V32: =IF(OR(tickets_cleaned[[#This Row],[resolution_time_hours]]="", tickets_cleaned[[#This Row],[resolution_time_hours]]<0),"",tickets_cleaned[[#This Row],[resolution_time_hours]])
A33: 32 | B33: Robert Wilson | C33: zstewart@example.org | D33: 60 | E33: Male | F33: GoPro Action Camera | G33: 44550 | H33: Technical issue | I33: Product compatibility | J33: I'm having an issue with the {product_purchased}. Please assist. The seller has sold the item for $29.89. When we receive your replacement, we will exchange the item for a full refund or exchange immediately upon I've already contacted customer support multiple times, but the issue remains unresolved. | K33: Closed | L33: Certain myself month past tree benefit. | M33: Medium | N33: Social media | O33: 45078.279 | P33: 45078.303 | Q33: 3 | R33: 0 | S33: 1 | T33: 0 | U33: 0 | V33: =IF(OR(tickets_cleaned[[#This Row],[resolution_time_hours]]="", tickets_cleaned[[#This Row],[resolution_time_hours]]<0),"",tickets_cleaned[[#This Row],[resolution_time_hours]]) -> 0
A34: 33 | B34: Christina Gray | C34: greenkeith@example.net | D34: 36 | E34: Female | F34: Fitbit Charge | G34: 44537 | H34: Billing inquiry | I34: Product recommendation | J34: I've noticed a software bug in the {product_purchased} app. It's causing data loss and unexpected errors. How can I resolve this issue? I need assistance as soon as possible because it's affecting my work and productivity. | K34: Pending Customer Response | M34: Medium | N34: Chat | O34: 45078.817 | S34: 0 | T34: 1 | U34: 0 | V34: =IF(OR(tickets_cleaned[[#This Row],[resolution_time_hours]]="", tickets_cleaned[[#This Row],[resolution_time_hours]]<0),"",tickets_cleaned[[#This Row],[resolution_time_hours]])
A35: 34 | B35: Timothy Lyons | C35: darlenelee@example.org | D35: 50 | E35: Male | F35: Autodesk AutoCAD | G35: 44539 | H35: Refund request | I35: Hardware issue | J35: I'm having an issue with the {product_purchased}. Please assist. We hope that every vendor takes the time it takes in to do the following: "Remove the product from your account - notify consumers, call them, make their I'm concerned about the security of my {product_purchased} and would like to ensure that my data is safe. | K35: Closed | L35: However financial development significant camera job every. | M35: Critical | N35: Social media | O35: 45078.084 | P35: 45078.768 | Q35: 5 | R35: 16 | S35: 1 | T35: 0 | U35: 0 | V35: =IF(OR(tickets_cleaned[[#This Row],[resolution_time_hours]]="", tickets_cleaned[[#This Row],[resolution_time_hours]]<0),"",tickets_cleaned[[#This Row],[resolution_time_hours]]) -> 16
A36: 35 | B36: Stacy Jones | C36: fernandezmark@example.org | D36: 27 | E36: Male | F36: Microsoft Xbox Controller | G36: 44295 | H36: Refund request | I36: Installation support | J36: I'm having an issue with the {product_purchased}. Please assist. 3-3 We are in, the first day, at the {product_purchased}. Please assist. 3-2 Please assist us I've recently updated the firmware of my {product_purchased}, and the issue started happening afterward. Could it be related to the update? | K36: Pending Customer Response | M36: Low | N36: Chat | O36: 45078.868 | S36: 0 | T36: 1 | U36: 0 | V36: =IF(OR(tickets_cleaned[[#This Row],[resolution_time_hours]]="", tickets_cleaned[[#This Row],[resolution_time_hours]]<0),"",tickets_cleaned[[#This Row],[resolution_time_hours]])
A37: 36 | B37: Joann King | C37: jessica10@example.org | D37: 24 | E37: Other | F37: GoPro Hero | G37: 44117 | H37: Cancellation request | I37: Product recommendation | J37: I've recently set up my {product_purchased}, but it fails to connect to any available networks. What steps should I take to troubleshoot this issue? If you know the answer, please let me know. Do I I've noticed a sudden decrease in battery life on my {product_purchased}. It used to last much longer. | K37: Closed | L37: Reach paper ability effort learn. | M37: High | N37: Chat | O37: 45078.331 | P37: 45078.01 | Q37: 1 | S37: 1 | T37: 0 | U37: 1 | V37: =IF(OR(tickets_cleaned[[#This Row],[resolution_time_hours]]="", tickets_cleaned[[#This Row],[resolution_time_hours]]<0),"",tickets_cleaned[[#This Row],[resolution_time_hours]])
A38: 37 | B38: Ruben Henry | C38: katherinehoward@example.net | D38: 65 | E38: Female | F38: Canon EOS | G38: 43904 | H38: Refund request | I38: Hardware issue | J38: I'm having an issue with the {product_purchased}. Please assist. I have to ask for support from you, the customers, before the item's arrival and I can't do that. In the short term, will you pay me I've followed the troubleshooting steps mentioned in the user manual, but the issue persists. | K38: Pending Customer Response | M38: Medium | N38: Email | O38: 45078.661 | S38: 0 | T38: 1 | U38: 0 | V38: =IF(OR(tickets_cleaned[[#This Row],[resolution_time_hours]]="", tickets_cleaned[[#This Row],[resolution_time_hours]]<0),"",tickets_cleaned[[#This Row],[resolution_time_hours]])
A39: 38 | B39: Morgan Wagner | C39: elizabethlamb@example.com | D39: 39 | E39: Female | F39: Amazon Kindle | G39: 44076 | H39: Product inquiry | I39: Product compatibility | J39: I've forgotten my password for my {product_purchased} account, and the password reset option is not working. How can I recover my account? I can reset my password by entering the following: My password still valid: password is expired I've recently updated the firmware of my {product_purchased}, and the issue started happening afterward. Could it be related to the update? | K39: Open | M39: Medium | N39: Chat | S39: 0 | T39: 1 | U39: 0 | V39: =IF(OR(tickets_cleaned[[#This Row],[resolution_time_hours]]="", tickets_cleaned[[#This Row],[resolution_time_hours]]<0),"",tickets_cleaned[[#This Row],[resolution_time_hours]])
A40: 39 | B40: Kevin Ingram | C40: victor62@example.net | D40: 19 | E40: Male | F40: Google Pixel | G40: 44449 | H40: Technical issue | I40: Account access | J40: I'm having an issue with the {product_purchased}. Please assist. 1. Do I need to purchase a refund? There is a way to purchase a refund from ZEROHITS, but there's not a I'm unable to find the option to perform the desired action in the {product_purchased}. Could you please guide me through the steps? | K40: Closed | L40: North second between this cell opportunity movement. | M40: Critical | N40: Phone | O40: 45078.782 | P40: 45077.912 | Q40: 3 | S40: 1 | T40: 0 | U40: 0 | V40: =IF(OR(tickets_cleaned[[#This Row],[resolution_time_hours]]="", tickets_cleaned[[#This Row],[resolution_time_hours]]<0),"",tickets_cleaned[[#This Row],[resolution_time_hours]])
...

Sheet KPI Summary
A1: metric_name | B1: metric_value
A2: total_tickets | B2: 8469
A3: closed_tickets | B3: 2769
A4: backlog_tickets | B4: 5700
A5: closed_ticket_rate_pct | B5: 32.7
A6: backlog_rate_pct | B6: 67.3
A7: avg_resolution_time_hours | B7: 7.11
A8: avg_csat_rating | B8: 2.99
A9: low_csat_rate_pct | B9: 39.8
A12: Total Tickets | C12: =TEXT(_xlfn.XLOOKUP("total_tickets",'KPI Summary'!$A:$A,'KPI Summary'!$B:$B,""),"#,##0") -> 8,469 | F12: Closed Tickets | H12: =TEXT(_xlfn.XLOOKUP("closed_tickets", 'KPI Summary'!$A:$A,'KPI Summary'!$B:$B),"#,##0") -> 2,769 | L12: Backog Tickets | N12: =TEXT(_xlfn.XLOOKUP("backlog_tickets", 'KPI Summary'!$A:$A,'KPI Summary'!$B:$B),"#,##0") -> 5,700 | Q12: Closed Rate | S12: =TEXT(_xlfn.XLOOKUP("closed_ticket_rate_pct", 'KPI Summary'!$A:$A,'KPI Summary'!$B:$B), "0.00")&"%" -> 32.70%
A16: Backlog Rate | C16: =TEXT(_xlfn.XLOOKUP("backlog_rate_pct",'KPI Summary'!$A:$A,'KPI Summary'!$B:$B), "0.00")&"%" -> 67.30% | F16: Avg CSAT | H16: =TEXT(_xlfn.XLOOKUP("avg_csat_rating", 'KPI Summary'!$A:$A,'KPI Summary'!$B:$B), "0.00")&"%" -> 2.99% | L16: Avg Resolution | N16: =TEXT(_xlfn.XLOOKUP("avg_resolution_time_hours", 'KPI Summary'!$A:$A,'KPI Summary'!$B:$B), "0.00")&"%" -> 7.11% | Q16: Low CSAT Rate | S16: =TEXT(_xlfn.XLOOKUP("low_csat_rate_pct",'KPI Summary'!$A:$A,'KPI Summary'!$B:$B), "0.00")&"%" -> 39.80%

Sheet By_Category
A1: ticket_type | B1: total_tickets | C1: closed_tickets | D1: closed_rate_pct
A2: Billing inquiry | B2: 1634 | C2: 544 | D2: 33.29
A3: Product inquiry | B3: 1641 | C3: 533 | D3: 32.48
A4: Cancellation request | B4: 1695 | C4: 516 | D4: 30.44
A5: Technical issue | B5: 1747 | C5: 580 | D5: 33.2
A6: Refund request | B6: 1752 | C6: 596 | D6: 34.02

Sheet By_Priority
A1: ticket_priority | B1: total_tickets | C1: backlog_tickets | D1: backlog_rate_pct
A2: Critical | B2: 2129 | C2: 1403 | D2: 65.9
A3: High | B3: 2085 | C3: 1380 | D3: 66.19
A4: Medium | B4: 2192 | C4: 1498 | D4: 68.34
A5: Low | B5: 2063 | C5: 1419 | D5: 68.78

Sheet By_Channel
A1: ticket_channel | B1: total_tickets | C1: closed_tickets | D1: avg_resolution_time_hours
A2: Email | B2: 2143 | C2: 720 | D2: 7.14
A3: Phone | B3: 2132 | C3: 691 | D3: 6.8
A4: Social media | B4: 2121 | C4: 684 | D4: 7.44
A5: Chat | B5: 2073 | C5: 674 | D5: 7.04

Sheet CSAT_Summary
A1: ticket_type | B1: rated_tickets | C1: avg_csat_rating | D1: low_csat_rate_pct
A2: Product inquiry | B2: 533 | C2: 3.02 | D2: 37.34
A3: Cancellation request | B3: 516 | C3: 3.03 | D3: 38.37
A4: Technical issue | B4: 580 | C4: 2.96 | D4: 40.34
A5: Billing inquiry | B5: 544 | C5: 3.03 | D5: 40.99
A6: Refund request | B6: 596 | C6: 2.93 | D6: 41.61

Sheet Monthly_Trend
A1: response_month | B1: total_tickets | C1: closed_tickets | D1: avg_csat_rating
A2: 45047 | B2: 175 | C2: 80 | D2: 3.04
A3: 45078 | B3: 5475 | C3: 2689 | D3: 2.99

Sheet Pivot tables
A1: KPIs
A3: Count of ticket_id | B3: Average of customer_satisfaction_rating | C3: Average of resolution_time_hours | D3: Average of Resolution_Time_Clean
A4: 8469 | B4: 2.9913326 | C4: 7.1096866 | D4: 7.1096866
A10: Count of ticket_id | B10: Sum of is_closed | C10: Resolution Rate (%) | D10: Backlog
A11: 8469 | B11: 2769 | C11: =GETPIVOTDATA("Sum of is_closed",$A$10)/GETPIVOTDATA("Count of ticket_id",$A$10) -> 0.32695714 | D11: =GETPIVOTDATA("Count of ticket_id",$A$10)-GETPIVOTDATA("Sum of is_closed",$A$10) -> 5700
A14: VOLUME
A15: Tickets per month
A16: Row Labels | B16: Count of ticket_id
A17: Jan | B17: 736
A18: Feb | B18: 715
A19: Mar | B19: 672
A20: Apr | B20: 718
A21: May | B21: 701
A22: Jun | B22: 678
A23: Jul | B23: 727
A24: Aug | B24: 691
A25: Sep | B25: 696
A26: Oct | B26: 735
A27: Nov | B27: 704
A28: Dec | B28: 696
A29: Grand Total | B29: 8469
A31: Tickets per status
A32: Row Labels | B32: Count of ticket_id
A33: Pending Customer Response | B33: 2881
A34: Open | B34: 2819
A35: Closed | B35: 2769
A36: Grand Total | B36: 8469
A48: PERFORMANCE
A49: Avg Resolution Time per month
A51: Row Labels | B51: Average of Resolution_Time_Clean
A52: May | B52: 0
A53: Jun | B53: 7.1198288
A54: Grand Total | B54: 7.1096866
A61: Resolution Time por Type
A62: Row Labels | B62: Average of Resolution_Time_Clean
A63: Billing inquiry | B63: 6.5494505
A64: Cancellation request | B64: 7.2264151
A65: Product inquiry | B65: 7.2256809
A66: Refund request | B66: 7.6315789
A67: Technical issue | B67: 6.8918033
...
